const x = 10

try{
    x=3

}catch(e) {
    console.log(`Erro: ${e}`);
}

console.log('Continuando');